[2025-02-05T11:39:59.385+0530] {local_task_job_runner.py:123} INFO - ::group::Pre task execution logs
[2025-02-05T11:39:59.392+0530] {taskinstance.py:2613} INFO - Dependencies all met for dep_context=non-requeueable deps ti=<TaskInstance: brewery_data_pipeline.fetch_store_brewery_data manual__2025-02-05T05:59:49.122984+00:00 [queued]>
[2025-02-05T11:39:59.397+0530] {taskinstance.py:2613} INFO - Dependencies all met for dep_context=requeueable deps ti=<TaskInstance: brewery_data_pipeline.fetch_store_brewery_data manual__2025-02-05T05:59:49.122984+00:00 [queued]>
[2025-02-05T11:39:59.397+0530] {taskinstance.py:2866} INFO - Starting attempt 3 of 3
[2025-02-05T11:39:59.413+0530] {taskinstance.py:2889} INFO - Executing <Task(PythonOperator): fetch_store_brewery_data> on 2025-02-05 05:59:49.122984+00:00
[2025-02-05T11:39:59.418+0530] {standard_task_runner.py:72} INFO - Started process 268709 to run task
[2025-02-05T11:39:59.421+0530] {standard_task_runner.py:104} INFO - Running: ['airflow', 'tasks', 'run', 'brewery_data_pipeline', 'fetch_store_brewery_data', 'manual__2025-02-05T05:59:49.122984+00:00', '--job-id', '29', '--raw', '--subdir', 'DAGS_FOLDER/pipeline_miniproject.py', '--cfg-path', '/tmp/tmpk6q3h_2e']
[2025-02-05T11:39:59.422+0530] {standard_task_runner.py:105} INFO - Job 29: Subtask fetch_store_brewery_data
[2025-02-05T11:39:59.454+0530] {task_command.py:467} INFO - Running <TaskInstance: brewery_data_pipeline.fetch_store_brewery_data manual__2025-02-05T05:59:49.122984+00:00 [running]> on host umang-Latitude-7490
[2025-02-05T11:39:59.504+0530] {taskinstance.py:3132} INFO - Exporting env vars: AIRFLOW_CTX_DAG_OWNER='airflow' AIRFLOW_CTX_DAG_ID='brewery_data_pipeline' AIRFLOW_CTX_TASK_ID='fetch_store_brewery_data' AIRFLOW_CTX_EXECUTION_DATE='2025-02-05T05:59:49.122984+00:00' AIRFLOW_CTX_TRY_NUMBER='3' AIRFLOW_CTX_DAG_RUN_ID='manual__2025-02-05T05:59:49.122984+00:00'
[2025-02-05T11:39:59.505+0530] {logging_mixin.py:190} INFO - Task instance is in running state
[2025-02-05T11:39:59.505+0530] {logging_mixin.py:190} INFO -  Previous state of the Task instance: queued
[2025-02-05T11:39:59.505+0530] {logging_mixin.py:190} INFO - Current task name:fetch_store_brewery_data state:running start_date:2025-02-05 06:09:59.393057+00:00
[2025-02-05T11:39:59.505+0530] {logging_mixin.py:190} INFO - Dag name:brewery_data_pipeline and current dag run status:running
[2025-02-05T11:39:59.506+0530] {taskinstance.py:731} INFO - ::endgroup::
[2025-02-05T11:40:24.531+0530] {pipeline_miniproject.py:35} ERROR - API request failed: HTTPSConnectionPool(host='api.openbrewerydb.org', port=443): Max retries exceeded with url: /v1/breweries (Caused by NameResolutionError("<urllib3.connection.HTTPSConnection object at 0x76fce3806a50>: Failed to resolve 'api.openbrewerydb.org' ([Errno -3] Temporary failure in name resolution)"))
[2025-02-05T11:40:24.532+0530] {taskinstance.py:3311} ERROR - Task failed with exception
Traceback (most recent call last):
  File "/home/umang/Dataslush_umang/airflow_env/lib/python3.12/site-packages/urllib3/connection.py", line 198, in _new_conn
    sock = connection.create_connection(
           ^^^^^^^^^^^^^^^^^^^^^^^^^^^^^
  File "/home/umang/Dataslush_umang/airflow_env/lib/python3.12/site-packages/urllib3/util/connection.py", line 60, in create_connection
    for res in socket.getaddrinfo(host, port, family, socket.SOCK_STREAM):
               ^^^^^^^^^^^^^^^^^^^^^^^^^^^^^^^^^^^^^^^^^^^^^^^^^^^^^^^^^^
  File "/usr/lib/python3.12/socket.py", line 963, in getaddrinfo
    for res in _socket.getaddrinfo(host, port, family, type, proto, flags):
               ^^^^^^^^^^^^^^^^^^^^^^^^^^^^^^^^^^^^^^^^^^^^^^^^^^^^^^^^^^^
socket.gaierror: [Errno -3] Temporary failure in name resolution

The above exception was the direct cause of the following exception:

Traceback (most recent call last):
  File "/home/umang/Dataslush_umang/airflow_env/lib/python3.12/site-packages/urllib3/connectionpool.py", line 787, in urlopen
    response = self._make_request(
               ^^^^^^^^^^^^^^^^^^^
  File "/home/umang/Dataslush_umang/airflow_env/lib/python3.12/site-packages/urllib3/connectionpool.py", line 488, in _make_request
    raise new_e
  File "/home/umang/Dataslush_umang/airflow_env/lib/python3.12/site-packages/urllib3/connectionpool.py", line 464, in _make_request
    self._validate_conn(conn)
  File "/home/umang/Dataslush_umang/airflow_env/lib/python3.12/site-packages/urllib3/connectionpool.py", line 1093, in _validate_conn
    conn.connect()
  File "/home/umang/Dataslush_umang/airflow_env/lib/python3.12/site-packages/urllib3/connection.py", line 704, in connect
    self.sock = sock = self._new_conn()
                       ^^^^^^^^^^^^^^^^
  File "/home/umang/Dataslush_umang/airflow_env/lib/python3.12/site-packages/urllib3/connection.py", line 205, in _new_conn
    raise NameResolutionError(self.host, self, e) from e
urllib3.exceptions.NameResolutionError: <urllib3.connection.HTTPSConnection object at 0x76fce3806a50>: Failed to resolve 'api.openbrewerydb.org' ([Errno -3] Temporary failure in name resolution)

The above exception was the direct cause of the following exception:

Traceback (most recent call last):
  File "/home/umang/Dataslush_umang/airflow_env/lib/python3.12/site-packages/requests/adapters.py", line 667, in send
    resp = conn.urlopen(
           ^^^^^^^^^^^^^
  File "/home/umang/Dataslush_umang/airflow_env/lib/python3.12/site-packages/urllib3/connectionpool.py", line 841, in urlopen
    retries = retries.increment(
              ^^^^^^^^^^^^^^^^^^
  File "/home/umang/Dataslush_umang/airflow_env/lib/python3.12/site-packages/urllib3/util/retry.py", line 519, in increment
    raise MaxRetryError(_pool, url, reason) from reason  # type: ignore[arg-type]
    ^^^^^^^^^^^^^^^^^^^^^^^^^^^^^^^^^^^^^^^^^^^^^^^^^^^
urllib3.exceptions.MaxRetryError: HTTPSConnectionPool(host='api.openbrewerydb.org', port=443): Max retries exceeded with url: /v1/breweries (Caused by NameResolutionError("<urllib3.connection.HTTPSConnection object at 0x76fce3806a50>: Failed to resolve 'api.openbrewerydb.org' ([Errno -3] Temporary failure in name resolution)"))

During handling of the above exception, another exception occurred:

Traceback (most recent call last):
  File "/home/umang/airflow/dags/pipeline_miniproject.py", line 31, in fetch_and_store_data
    response = requests.get(url)
               ^^^^^^^^^^^^^^^^^
  File "/home/umang/Dataslush_umang/airflow_env/lib/python3.12/site-packages/requests/api.py", line 73, in get
    return request("get", url, params=params, **kwargs)
           ^^^^^^^^^^^^^^^^^^^^^^^^^^^^^^^^^^^^^^^^^^^^
  File "/home/umang/Dataslush_umang/airflow_env/lib/python3.12/site-packages/requests/api.py", line 59, in request
    return session.request(method=method, url=url, **kwargs)
           ^^^^^^^^^^^^^^^^^^^^^^^^^^^^^^^^^^^^^^^^^^^^^^^^^
  File "/home/umang/Dataslush_umang/airflow_env/lib/python3.12/site-packages/requests/sessions.py", line 589, in request
    resp = self.send(prep, **send_kwargs)
           ^^^^^^^^^^^^^^^^^^^^^^^^^^^^^^
  File "/home/umang/Dataslush_umang/airflow_env/lib/python3.12/site-packages/requests/sessions.py", line 703, in send
    r = adapter.send(request, **kwargs)
        ^^^^^^^^^^^^^^^^^^^^^^^^^^^^^^^
  File "/home/umang/Dataslush_umang/airflow_env/lib/python3.12/site-packages/requests/adapters.py", line 700, in send
    raise ConnectionError(e, request=request)
requests.exceptions.ConnectionError: HTTPSConnectionPool(host='api.openbrewerydb.org', port=443): Max retries exceeded with url: /v1/breweries (Caused by NameResolutionError("<urllib3.connection.HTTPSConnection object at 0x76fce3806a50>: Failed to resolve 'api.openbrewerydb.org' ([Errno -3] Temporary failure in name resolution)"))

During handling of the above exception, another exception occurred:

Traceback (most recent call last):
  File "/home/umang/Dataslush_umang/airflow_env/lib/python3.12/site-packages/airflow/models/taskinstance.py", line 762, in _execute_task
    result = _execute_callable(context=context, **execute_callable_kwargs)
             ^^^^^^^^^^^^^^^^^^^^^^^^^^^^^^^^^^^^^^^^^^^^^^^^^^^^^^^^^^^^^
  File "/home/umang/Dataslush_umang/airflow_env/lib/python3.12/site-packages/airflow/models/taskinstance.py", line 733, in _execute_callable
    return ExecutionCallableRunner(
           ^^^^^^^^^^^^^^^^^^^^^^^^
  File "/home/umang/Dataslush_umang/airflow_env/lib/python3.12/site-packages/airflow/utils/operator_helpers.py", line 252, in run
    return self.func(*args, **kwargs)
           ^^^^^^^^^^^^^^^^^^^^^^^^^^
  File "/home/umang/Dataslush_umang/airflow_env/lib/python3.12/site-packages/airflow/models/baseoperator.py", line 422, in wrapper
    return func(self, *args, **kwargs)
           ^^^^^^^^^^^^^^^^^^^^^^^^^^^
  File "/home/umang/Dataslush_umang/airflow_env/lib/python3.12/site-packages/airflow/operators/python.py", line 238, in execute
    return_value = self.execute_callable()
                   ^^^^^^^^^^^^^^^^^^^^^^^
  File "/home/umang/Dataslush_umang/airflow_env/lib/python3.12/site-packages/airflow/operators/python.py", line 256, in execute_callable
    return runner.run(*self.op_args, **self.op_kwargs)
           ^^^^^^^^^^^^^^^^^^^^^^^^^^^^^^^^^^^^^^^^^^^
  File "/home/umang/Dataslush_umang/airflow_env/lib/python3.12/site-packages/airflow/utils/operator_helpers.py", line 252, in run
    return self.func(*args, **kwargs)
           ^^^^^^^^^^^^^^^^^^^^^^^^^^
  File "/home/umang/airflow/dags/pipeline_miniproject.py", line 36, in fetch_and_store_data
    raise Exception(f"API request failed: {e}")
Exception: API request failed: HTTPSConnectionPool(host='api.openbrewerydb.org', port=443): Max retries exceeded with url: /v1/breweries (Caused by NameResolutionError("<urllib3.connection.HTTPSConnection object at 0x76fce3806a50>: Failed to resolve 'api.openbrewerydb.org' ([Errno -3] Temporary failure in name resolution)"))
[2025-02-05T11:40:24.560+0530] {logging_mixin.py:190} INFO - Task instance in failure state
[2025-02-05T11:40:24.560+0530] {logging_mixin.py:190} INFO - Task start:2025-02-05 06:09:59.393057+00:00 end:2025-02-05 06:10:24.559454+00:00 duration:25.166397
[2025-02-05T11:40:24.561+0530] {logging_mixin.py:190} INFO - Task:<Task(PythonOperator): fetch_store_brewery_data> dag:<DAG: brewery_data_pipeline> dagrun:<DagRun brewery_data_pipeline @ 2025-02-05 05:59:49.122984+00:00: manual__2025-02-05T05:59:49.122984+00:00, state:running, queued_at: 2025-02-05 05:59:49.139744+00:00. externally triggered: True>
[2025-02-05T11:40:24.561+0530] {logging_mixin.py:190} INFO - Failure caused by API request failed: HTTPSConnectionPool(host='api.openbrewerydb.org', port=443): Max retries exceeded with url: /v1/breweries (Caused by NameResolutionError("<urllib3.connection.HTTPSConnection object at 0x76fce3806a50>: Failed to resolve 'api.openbrewerydb.org' ([Errno -3] Temporary failure in name resolution)"))
[2025-02-05T11:40:24.561+0530] {taskinstance.py:1225} INFO - Marking task as FAILED. dag_id=brewery_data_pipeline, task_id=fetch_store_brewery_data, run_id=manual__2025-02-05T05:59:49.122984+00:00, execution_date=20250205T055949, start_date=20250205T060959, end_date=20250205T061024
[2025-02-05T11:40:24.577+0530] {taskinstance.py:340} INFO - ::group::Post task execution logs
[2025-02-05T11:40:24.577+0530] {standard_task_runner.py:124} ERROR - Failed to execute job 29 for task fetch_store_brewery_data (API request failed: HTTPSConnectionPool(host='api.openbrewerydb.org', port=443): Max retries exceeded with url: /v1/breweries (Caused by NameResolutionError("<urllib3.connection.HTTPSConnection object at 0x76fce3806a50>: Failed to resolve 'api.openbrewerydb.org' ([Errno -3] Temporary failure in name resolution)")); 268709)
Traceback (most recent call last):
  File "/home/umang/Dataslush_umang/airflow_env/lib/python3.12/site-packages/urllib3/connection.py", line 198, in _new_conn
    sock = connection.create_connection(
           ^^^^^^^^^^^^^^^^^^^^^^^^^^^^^
  File "/home/umang/Dataslush_umang/airflow_env/lib/python3.12/site-packages/urllib3/util/connection.py", line 60, in create_connection
    for res in socket.getaddrinfo(host, port, family, socket.SOCK_STREAM):
               ^^^^^^^^^^^^^^^^^^^^^^^^^^^^^^^^^^^^^^^^^^^^^^^^^^^^^^^^^^
  File "/usr/lib/python3.12/socket.py", line 963, in getaddrinfo
    for res in _socket.getaddrinfo(host, port, family, type, proto, flags):
               ^^^^^^^^^^^^^^^^^^^^^^^^^^^^^^^^^^^^^^^^^^^^^^^^^^^^^^^^^^^
socket.gaierror: [Errno -3] Temporary failure in name resolution

The above exception was the direct cause of the following exception:

Traceback (most recent call last):
  File "/home/umang/Dataslush_umang/airflow_env/lib/python3.12/site-packages/urllib3/connectionpool.py", line 787, in urlopen
    response = self._make_request(
               ^^^^^^^^^^^^^^^^^^^
  File "/home/umang/Dataslush_umang/airflow_env/lib/python3.12/site-packages/urllib3/connectionpool.py", line 488, in _make_request
    raise new_e
  File "/home/umang/Dataslush_umang/airflow_env/lib/python3.12/site-packages/urllib3/connectionpool.py", line 464, in _make_request
    self._validate_conn(conn)
  File "/home/umang/Dataslush_umang/airflow_env/lib/python3.12/site-packages/urllib3/connectionpool.py", line 1093, in _validate_conn
    conn.connect()
  File "/home/umang/Dataslush_umang/airflow_env/lib/python3.12/site-packages/urllib3/connection.py", line 704, in connect
    self.sock = sock = self._new_conn()
                       ^^^^^^^^^^^^^^^^
  File "/home/umang/Dataslush_umang/airflow_env/lib/python3.12/site-packages/urllib3/connection.py", line 205, in _new_conn
    raise NameResolutionError(self.host, self, e) from e
urllib3.exceptions.NameResolutionError: <urllib3.connection.HTTPSConnection object at 0x76fce3806a50>: Failed to resolve 'api.openbrewerydb.org' ([Errno -3] Temporary failure in name resolution)

The above exception was the direct cause of the following exception:

Traceback (most recent call last):
  File "/home/umang/Dataslush_umang/airflow_env/lib/python3.12/site-packages/requests/adapters.py", line 667, in send
    resp = conn.urlopen(
           ^^^^^^^^^^^^^
  File "/home/umang/Dataslush_umang/airflow_env/lib/python3.12/site-packages/urllib3/connectionpool.py", line 841, in urlopen
    retries = retries.increment(
              ^^^^^^^^^^^^^^^^^^
  File "/home/umang/Dataslush_umang/airflow_env/lib/python3.12/site-packages/urllib3/util/retry.py", line 519, in increment
    raise MaxRetryError(_pool, url, reason) from reason  # type: ignore[arg-type]
    ^^^^^^^^^^^^^^^^^^^^^^^^^^^^^^^^^^^^^^^^^^^^^^^^^^^
urllib3.exceptions.MaxRetryError: HTTPSConnectionPool(host='api.openbrewerydb.org', port=443): Max retries exceeded with url: /v1/breweries (Caused by NameResolutionError("<urllib3.connection.HTTPSConnection object at 0x76fce3806a50>: Failed to resolve 'api.openbrewerydb.org' ([Errno -3] Temporary failure in name resolution)"))

During handling of the above exception, another exception occurred:

Traceback (most recent call last):
  File "/home/umang/airflow/dags/pipeline_miniproject.py", line 31, in fetch_and_store_data
    response = requests.get(url)
               ^^^^^^^^^^^^^^^^^
  File "/home/umang/Dataslush_umang/airflow_env/lib/python3.12/site-packages/requests/api.py", line 73, in get
    return request("get", url, params=params, **kwargs)
           ^^^^^^^^^^^^^^^^^^^^^^^^^^^^^^^^^^^^^^^^^^^^
  File "/home/umang/Dataslush_umang/airflow_env/lib/python3.12/site-packages/requests/api.py", line 59, in request
    return session.request(method=method, url=url, **kwargs)
           ^^^^^^^^^^^^^^^^^^^^^^^^^^^^^^^^^^^^^^^^^^^^^^^^^
  File "/home/umang/Dataslush_umang/airflow_env/lib/python3.12/site-packages/requests/sessions.py", line 589, in request
    resp = self.send(prep, **send_kwargs)
           ^^^^^^^^^^^^^^^^^^^^^^^^^^^^^^
  File "/home/umang/Dataslush_umang/airflow_env/lib/python3.12/site-packages/requests/sessions.py", line 703, in send
    r = adapter.send(request, **kwargs)
        ^^^^^^^^^^^^^^^^^^^^^^^^^^^^^^^
  File "/home/umang/Dataslush_umang/airflow_env/lib/python3.12/site-packages/requests/adapters.py", line 700, in send
    raise ConnectionError(e, request=request)
requests.exceptions.ConnectionError: HTTPSConnectionPool(host='api.openbrewerydb.org', port=443): Max retries exceeded with url: /v1/breweries (Caused by NameResolutionError("<urllib3.connection.HTTPSConnection object at 0x76fce3806a50>: Failed to resolve 'api.openbrewerydb.org' ([Errno -3] Temporary failure in name resolution)"))

During handling of the above exception, another exception occurred:

Traceback (most recent call last):
  File "/home/umang/Dataslush_umang/airflow_env/lib/python3.12/site-packages/airflow/task/task_runner/standard_task_runner.py", line 117, in _start_by_fork
    ret = args.func(args, dag=self.dag)
          ^^^^^^^^^^^^^^^^^^^^^^^^^^^^^
  File "/home/umang/Dataslush_umang/airflow_env/lib/python3.12/site-packages/airflow/cli/cli_config.py", line 49, in command
    return func(*args, **kwargs)
           ^^^^^^^^^^^^^^^^^^^^^
  File "/home/umang/Dataslush_umang/airflow_env/lib/python3.12/site-packages/airflow/utils/cli.py", line 116, in wrapper
    return f(*args, **kwargs)
           ^^^^^^^^^^^^^^^^^^
  File "/home/umang/Dataslush_umang/airflow_env/lib/python3.12/site-packages/airflow/cli/commands/task_command.py", line 483, in task_run
    task_return_code = _run_task_by_selected_method(args, _dag, ti)
                       ^^^^^^^^^^^^^^^^^^^^^^^^^^^^^^^^^^^^^^^^^^^^
  File "/home/umang/Dataslush_umang/airflow_env/lib/python3.12/site-packages/airflow/cli/commands/task_command.py", line 256, in _run_task_by_selected_method
    return _run_raw_task(args, ti)
           ^^^^^^^^^^^^^^^^^^^^^^^
  File "/home/umang/Dataslush_umang/airflow_env/lib/python3.12/site-packages/airflow/cli/commands/task_command.py", line 341, in _run_raw_task
    return ti._run_raw_task(
           ^^^^^^^^^^^^^^^^^
  File "/home/umang/Dataslush_umang/airflow_env/lib/python3.12/site-packages/airflow/utils/session.py", line 97, in wrapper
    return func(*args, session=session, **kwargs)
           ^^^^^^^^^^^^^^^^^^^^^^^^^^^^^^^^^^^^^^
  File "/home/umang/Dataslush_umang/airflow_env/lib/python3.12/site-packages/airflow/models/taskinstance.py", line 3005, in _run_raw_task
    return _run_raw_task(
           ^^^^^^^^^^^^^^
  File "/home/umang/Dataslush_umang/airflow_env/lib/python3.12/site-packages/airflow/models/taskinstance.py", line 273, in _run_raw_task
    TaskInstance._execute_task_with_callbacks(
  File "/home/umang/Dataslush_umang/airflow_env/lib/python3.12/site-packages/airflow/models/taskinstance.py", line 3159, in _execute_task_with_callbacks
    result = self._execute_task(context, task_orig)
             ^^^^^^^^^^^^^^^^^^^^^^^^^^^^^^^^^^^^^^
  File "/home/umang/Dataslush_umang/airflow_env/lib/python3.12/site-packages/airflow/models/taskinstance.py", line 3183, in _execute_task
    return _execute_task(self, context, task_orig)
           ^^^^^^^^^^^^^^^^^^^^^^^^^^^^^^^^^^^^^^^
  File "/home/umang/Dataslush_umang/airflow_env/lib/python3.12/site-packages/airflow/models/taskinstance.py", line 762, in _execute_task
    result = _execute_callable(context=context, **execute_callable_kwargs)
             ^^^^^^^^^^^^^^^^^^^^^^^^^^^^^^^^^^^^^^^^^^^^^^^^^^^^^^^^^^^^^
  File "/home/umang/Dataslush_umang/airflow_env/lib/python3.12/site-packages/airflow/models/taskinstance.py", line 733, in _execute_callable
    return ExecutionCallableRunner(
           ^^^^^^^^^^^^^^^^^^^^^^^^
  File "/home/umang/Dataslush_umang/airflow_env/lib/python3.12/site-packages/airflow/utils/operator_helpers.py", line 252, in run
    return self.func(*args, **kwargs)
           ^^^^^^^^^^^^^^^^^^^^^^^^^^
  File "/home/umang/Dataslush_umang/airflow_env/lib/python3.12/site-packages/airflow/models/baseoperator.py", line 422, in wrapper
    return func(self, *args, **kwargs)
           ^^^^^^^^^^^^^^^^^^^^^^^^^^^
  File "/home/umang/Dataslush_umang/airflow_env/lib/python3.12/site-packages/airflow/operators/python.py", line 238, in execute
    return_value = self.execute_callable()
                   ^^^^^^^^^^^^^^^^^^^^^^^
  File "/home/umang/Dataslush_umang/airflow_env/lib/python3.12/site-packages/airflow/operators/python.py", line 256, in execute_callable
    return runner.run(*self.op_args, **self.op_kwargs)
           ^^^^^^^^^^^^^^^^^^^^^^^^^^^^^^^^^^^^^^^^^^^
  File "/home/umang/Dataslush_umang/airflow_env/lib/python3.12/site-packages/airflow/utils/operator_helpers.py", line 252, in run
    return self.func(*args, **kwargs)
           ^^^^^^^^^^^^^^^^^^^^^^^^^^
  File "/home/umang/airflow/dags/pipeline_miniproject.py", line 36, in fetch_and_store_data
    raise Exception(f"API request failed: {e}")
Exception: API request failed: HTTPSConnectionPool(host='api.openbrewerydb.org', port=443): Max retries exceeded with url: /v1/breweries (Caused by NameResolutionError("<urllib3.connection.HTTPSConnection object at 0x76fce3806a50>: Failed to resolve 'api.openbrewerydb.org' ([Errno -3] Temporary failure in name resolution)"))
[2025-02-05T11:40:24.598+0530] {local_task_job_runner.py:266} INFO - Task exited with return code 1
[2025-02-05T11:40:24.606+0530] {taskinstance.py:3895} INFO - 0 downstream tasks scheduled from follow-on schedule check
[2025-02-05T11:40:24.606+0530] {local_task_job_runner.py:245} INFO - ::endgroup::
